---


layout: post
title: Thinking in Java摘抄（异常）
tags: ["Tij"]
comments: false
---
## 异常

* “异常”这个词有“我对此感到意外”的意思。问题出现了，你也许不清楚该如何处理，但你的确知道不应该置之不理，你要停下来，看看是不是有别人或在别的地方，能够处理这个问题。只是在当前的环境中还没有足够的信息来解决这个问题，所以就把这个问题提交到一个更高级别的环境中，在那里将作出正确的决定。

  > 异常往往能降低错误处理代码的复杂度。如果不使用异常，那么就必须检查特定的错误，并在程序中的许多地方去处理它。而如果使用异常，那就不必在方法调用处进行检查，因为异常机制将保证能够捕获这个错误。理想情况下，只需在一个地方处理错误，即所谓的异常处理程序中。这种方式不仅节省代码，而且把“描述在正常执行过程中做什么事”的代码和“出了问题怎么办”的代码相分离。总之，与以前的错误处理方法相比，异常机制使代码的阅读、编写和调试工作更加井井有条。

* 取异常堆栈：

  > ```java
  > StringWriter trace = new StringWriter();
  > printStackTrace(new PrintWriter(trace));
  > logger.severe(trace.toString());
  > ```

* 异常说明使用了附加的关键字 throws，后面接一个所有潜在异常类型的列表，所以方法定义可能看起来像这样：

  ```java
  void f() throws TooBig, TooSmall, DivZero { // ...
  ```

  但是，要是这样写：

  ```java
  void f() { // ...
  ```

  就表示此方法不会抛出任何异常（除了从 RuntimeException 继承的异常，它们可以在没有异常说明的情况下被抛出，这些将在后面进行讨论）。

  代码必须与异常说明保持一致。如果方法里的代码产生了异常却没有进行处理，编译器会发现这个问题并提醒你：要么处理这个异常，要么就在异常说明中表明此方法将产生异常。通过这种自顶向下强制执行的异常说明机制，Java 在编译时就可以保证一定水平的异常正确性。

  不过还是有个能“作弊”的地方：可以声明方法将抛出异常，实际上却不抛出。编译器相信了这个声明，并强制此方法的用户像真的抛出异常那样使用这个方法。这样做的好处是，为异常先占个位子，以后就可以抛出这种异常而不用修改已有的代码。在定义抽象基类和接口时这种能力很重要，这样派生类或接口实现就能够抛出这些预先声明的异常。

  这种在编译时被强制检查的异常称为被检查的异常。

* printStackTrace() 方法所提供的信息可以通过 getStackTrace() 方法来直接访问，这个方法将返回一个由栈轨迹中的元素所构成的数组，其中每一个元素都表示栈中的一桢。元素 0 是栈顶元素，并且是调用序列中的最后一个方法调用（这个 Throwable 被创建和抛出之处）。数组中的最后一个元素和栈底是调用序列中的第一个方法调用。

* 有时希望把刚捕获的异常重新抛出，尤其是在使用 Exception 捕获所有异常的时候。既然已经得到了对当前异常对象的引用，可以直接把它重新抛出：

  ```java
  catch(Exception e) {
      System.out.println("An exception was thrown");
      throw e;
  }
  ```

  重抛异常会把异常抛给上一级环境中的异常处理程序，同一个 try 块的后续 catch 子句将被忽略。此外，异常对象的所有信息都得以保持，所以高一级环境中捕获此异常的处理程序可以从这个异常对象中得到所有信息。

  如果只是把当前异常对象重新抛出，那么 printStackTrace() 方法显示的将是原来异常抛出点的调用栈信息，而并非重新抛出点的信息。要想更新这个信息，可以调用 filInStackTrace() 方法，这将返回一个 Throwable 对象，它是通过把当前调用栈信息填入原来那个异常对象而建立的。

  有可能在捕获异常之后抛出另一种异常。这么做的话，得到的效果类似于使用 filInStackTrace()，有关原来异常发生点的信息会丢失，剩下的是与新的抛出点有关的信息。

* 在 Java 7 之前，如果遇到异常，则只能重新抛出该类型的异常。这导致在 Java 7 中修复的代码不精确。所以在 Java 7 之前，这无法编译：

  ```java
  class BaseException extends Exception {}
  class DerivedException extends BaseException {}
  
  public class PreciseRethrow {
      void catcher() throws DerivedException {
          try {
              throw new DerivedException();
          } catch(BaseException e) {
              throw e;
          }
      }
  }
  ```

  因为 catch 捕获了一个 BaseException，编译器强迫你声明 catcher() 抛出 BaseException，即使它实际上抛出了更具体的 DerivedException。从 Java 7 开始，这段代码就可以编译，这是一个很小但很有用的修复。

* 异常链：常常会想要在捕获一个异常后抛出另一个异常，并且希望把原始异常的信息保存下来，这被称为异常链。在 JDK1.4 以前，程序员必须自己编写代码来保存原始异常的信息。现在所有 Throwable 的子类在构造器中都可以接受一个 cause（因由）对象作为参数。这个 cause 就用来表示原始异常，这样通过把原始异常传递给新的异常，使得即使在当前位置创建并抛出了新的异常，也能通过这个异常链追踪到异常最初发生的位置。

  有趣的是，在 Throwable 的子类中，只有三种基本的异常类提供了带 cause 参数的构造器。它们是 Error（用于 Java 虚拟机报告系统错误）、Exception 以及 RuntimeException。如果要把其他类型的异常链接起来，应该使用 initCause0 方法而不是构造器。

  ```java
  DynamicFieldsException dfe =
                      new DynamicFieldsException();
              dfe.initCause(new NullPointerException());
              throw dfe;
  ```

  ```java
  catch(NoSuchFieldException e) {
  // Use constructor that takes "cause":
              throw new RuntimeException(e);
          }
  ```

* 异常限制：当覆盖方法的时候，只能抛出在基类方法的异常说明里列出的那些异常。这个限制很有用，因为这意味着，若当基类使用的代码应用到其派生类对象的时候，一样能够工作（当然，这是面向对象的基本概念），异常也不例外。

  下面例子演示了这种（在编译时）施加在异常上面的限制：

  > ```java
  > // exceptions/StormyInning.java
  > // Overridden methods can throw only the exceptions
  > // specified in their base-class versions, or exceptions
  > // derived from the base-class exceptions
  > class BaseballException extends Exception {}
  > class Foul extends BaseballException {}
  > class Strike extends BaseballException {}
  > abstract class Inning {
  >     Inning() throws BaseballException {}
  >     public void event() throws BaseballException {
  > // Doesn't actually have to throw anything
  >     }
  >     public abstract void atBat() throws Strike, Foul;
  >     public void walk() {} // Throws no checked exceptions
  > }
  > class StormException extends Exception {}
  > class RainedOut extends StormException {}
  > class PopFoul extends Foul {}
  > interface Storm {
  >     void event() throws RainedOut;
  >     void rainHard() throws RainedOut;
  > }
  > public class StormyInning extends Inning implements Storm {
  >     // OK to add new exceptions for constructors, but you
  > // must deal with the base constructor exceptions:
  >     public StormyInning()
  >             throws RainedOut, BaseballException {}
  >     public StormyInning(String s)
  >             throws BaseballException {}
  >     // Regular methods must conform to base class:
  > //- void walk() throws PopFoul {} //Compile error
  > // Interface CANNOT add exceptions to existing
  > // methods from the base class:
  > //- public void event() throws RainedOut {}
  > // If the method doesn't already exist in the
  > // base class, the exception is OK:
  >     @Override
  >     public void rainHard() throws RainedOut {}
  >     // You can choose to not throw any exceptions,
  > // even if the base version does:
  >     @Override
  >     public void event() {}
  >     // Overridden methods can throw inherited exceptions:
  >     @Override
  >     public void atBat() throws PopFoul {}
  >     public static void main(String[] args) {
  >         try {
  >             StormyInning si = new StormyInning();
  >             si.atBat();
  >         } catch(PopFoul e) {
  >             System.out.println("Pop foul");
  >         } catch(RainedOut e) {
  >             System.out.println("Rained out");
  >         } catch(BaseballException e) {
  >             System.out.println("Generic baseball exception");
  >         }
  > // Strike not thrown in derived version.
  >         try {
  > // What happens if you upcast?
  >             Inning i = new StormyInning();
  >             i.atBat();
  > // You must catch the exceptions from the
  > // base-class version of the method:
  >         } catch(Strike e) {
  >             System.out.println("Strike");
  >         } catch(Foul e) {
  >             System.out.println("Foul");
  >         } catch(RainedOut e) {
  >             System.out.println("Rained out");
  >         } catch(BaseballException e) {
  >             System.out.println("Generic baseball exception");
  >         }
  >     }
  > }
  > ```
  >
  > 在 Inning 类中，可以看到构造器和 event() 方法都声明将抛出异常，但实际上没有抛出。这种方式使你能强制用户去捕获可能在覆盖后的 event() 版本中增加的异常，所以它很合理。这对于抽象方法同样成立，比如 atBat()。
  >
  > 接口 Storm 包含了一个在 Inning 中定义的方法 event() 和一个不在 Inning 中定义的方法 rainHard()。这两个方法都抛出新的异常 RainedOut，如果 StormyInning 类在扩展 Inning 类的同时又实现了 Storm 接口，那么 Storm 里的 event() 方法就不能改变在 Inning 中的 event（方法的异常接口。否则的话，在使用基类的时候就不能判断是否捕获了正确的异常，所以这也很合理。当然，如果接口里定义的方法不是来自于基类，比如 rainHard()，那么此方法抛出什么样的异常都没有问题。
  >
  > 异常限制对构造器不起作用。你会发现 StormyInning 的构造器可以抛出任何异常，而不必理会基类构造器所抛出的异常。然而，因为基类构造器必须以这样或那样的方式被调用（这里默认构造器将自动被调用），派生类构造器的异常说明必须包含基类构造器的异常说明。
  >
  > 派生类构造器不能捕获基类构造器抛出的异常。
  >
  > StormyInning.walk() 不能通过编译是因为它抛出了异常，而 Inning.walk() 并没有声明此异常。如果编译器允许这么做的话，就可以在调用 Inning.walk() 的时候不用做异常处理了，而且当把它替换成 Inning 的派生类的对象时，这个方法就有可能会抛出异常，于是程序就失灵了。通过强制派生类遵守基类方法的异常说明，对象的可替换性得到了保证。
  >
  > 覆盖后的 event() 方法表明，派生类方法可以不抛出任何异常，即使它是基类所定义的异常。同样这是因为，假使基类的方法会抛出异常，这样做也不会破坏已有的程序，所以也没有问题。类似的情况出现在 atBat() 身上，它抛出的是 PopFoul，这个异常是继承自“会被基类的 atBat() 抛出”的 Foul，这样，如果你写的代码是同 Inning 打交道，并且调用了它的 atBat() 的话，那么肯定能捕获 Foul，而 PopFoul 是由 Foul 派生出来的，因此异常处理程序也能捕获 PopFoul。
  >
  > 最后一个值得注意的地方是 main()。这里可以看到，如果处理的刚好是 Stormylnning 对象的话，编译器只会强制要求你捕获这个类所抛出的异常。但是如果将它向上转型成基类型，那么编译器就会（正确地）要求你捕获基类的异常。所有这些限制都是为了能产生更为强壮的异常处理代码。
  >
  > 尽管在继承过程中，编译器会对异常说明做强制要求，但异常说明本身并不属于方法类型的一部分，方法类型是由方法的名字与参数的类型组成的。因此，不能基于异常说明来重载方法。此外，一个出现在基类方法的异常说明中的异常，不一定会出现在派生类方法的异常说明里。这点同继承的规则明显不同，在继承中，基类的方法必须出现在派生类里，换句话说，在继承和覆盖的过程中，某个特定方法的“异常说明的接口”不是变大了而是变小了——这恰好和类接口在继承时的情形相反。

* 构造器中的异常处理方式：

  

  > ```java
  >   try {
  >             NeedsCleanup2 nc4 = new NeedsCleanup2();
  >             try {
  >                 NeedsCleanup2 nc5 = new NeedsCleanup2();
  >                 try {
  >                 // ...
  >                 } finally {
  >                     nc5.dispose();
  >                 }
  >             } catch(ConstructionException e) { // nc5 const.
  >                 System.out.println(e);
  >             } finally {
  >                 nc4.dispose();
  >             }
  >         } catch(ConstructionException e) { // nc4 const.
  >             System.out.println(e);
  >         }
  > ```
  >
  > - [1] 相当简单，遵循了在可去除对象之后紧跟 try-finally 的原则。如果对象构造不会失败，就不需要任何 catch。
  > - [2] 为了构造和清理，可以看到将具有不能失败的构造器的对象分组在一起。
  > - [3] 展示了如何处理那些具有可以失败的构造器，且需要清理的对象。为了正确处理这种情况，事情变得很棘手，因为对于每一个构造，都必须包含在其自己的 try-finally 语句块中，并且每一个对象构造必须都跟随一个 try-finally 语句块以确保清理。

* Java 7 引入了 try-with-resources 语法来简化关闭资源操作：

  > ```java
  > public class TryWithResources {
  >     public static void main(String[] args) {
  >         try(
  >                 InputStream in = new FileInputStream(
  >                         new File("TryWithResources.java"))
  >         ) {
  >             int contents = in.read();
  >             // Process contents
  >         } catch(IOException e) {
  >             // Handle the error
  >         }
  >     }
  > }
  > ```
  >
  > 在 Java 7 之前，try 总是后面跟着一个 {，但是现在可以跟一个带括号的定义 - 这里是我们创建的 FileInputStream 对象。括号内的部分称为资源规范头（resource specification header）。现在可用于整个 try 块的其余部分。更重要的是，无论你如何退出 try 块（正常或异常），都会执行下面这个 finally 子句的等价物:
  >
  > ```java
  > public class MessyExceptions {
  >     public static void main(String[] args) {
  >         InputStream in = null;
  >         try {
  >             in = new FileInputStream(
  >                     new File("MessyExceptions.java"));
  >             int contents = in.read();
  >             // Process contents
  >         } catch(IOException e) {
  >             // Handle the error
  >         } finally {
  >             if(in != null) {
  >                 try {
  >                     in.close();
  >                 } catch(IOException e) {
  >                     // Handle the close() error
  >                 }
  >             }
  >         }
  >     }
  > }
  > ```
  >
  > 但不会编写那些杂乱而棘手的代码。这是一项重要的改进。
  >
  > 它是如何工作的？在 try-with-resources 定义子句中创建的对象（在括号内）必须实现 java.lang.AutoCloseable 接口，这个接口有一个方法：close()。当在 Java 7 中引入 AutoCloseable 时，许多接口和类被修改以实现它；查看 Javadocs 中的 AutoCloseable，可以找到所有实现该接口的类列表，其中包括 Stream 对象：
  >
  > ```java
  > public class StreamsAreAutoCloseable {
  >     public static void
  >     main(String[] args) throws IOException{
  >         try(
  >                 Stream<String> in = Files.lines(
  >                         Paths.get("StreamsAreAutoCloseable.java"));
  >                 PrintWriter outfile = new PrintWriter(
  >                         "Results.txt"); // [1]
  >         ) {
  >             in.skip(5)
  >                     .limit(1)
  >                     .map(String::toLowerCase)
  >                     .forEachOrdered(outfile::println);
  >         } // [2]
  >     }
  > }
  > ```
  >
  > - [1] 你在这里可以看到其他的特性：资源规范头中可以包含多个定义，并且通过分号进行分割（最后一个分号是可选的）。规范头中定义的每个对象都会在 try 语句块运行结束之后调用 close() 方法。
  > - [2] try-with-resources 里面的 try 语句块可以不包含 catch 或者 finally 语句而独立存在。在这里，IOException 被 main() 方法抛出，所以这里并不需要在 try 后面跟着一个 catch 语句块。
  >
  > Java 5 中的 Closeable 已经被修改，修改之后的接口继承了 AutoCloseable 接口。所以所有实现了 Closeable 接口的对象，都支持了 try-with-resources 特性。